Workbook
Name _DumProb: OFFSET([1]BetaSolver!$R$4,0,0,COUNTA([1]BetaSolver!$R$5:$R$1000),1)
Name AaaLoss_: '[1]Source Tables'!$B$6
Name AaaPD: '[1]Source Tables'!$F$6
Name ApprovedModel: [1]Backend!$B$12
Name BetaProb_: OFFSET([1]BetaSolver!$E$12,0,0,COUNTA([1]BetaSolver!$E$12:$E$1000),1)
Name CFR: [1]Lookups!$J$15:$J$25
Name CFR_: '[1]Model Inputs'!$D$17
Name CFRChoices: '[1]Source Tables'!$A$16:$A$26
Name ChartE2L_: OFFSET([1]BetaSolver!$A$12,0,0,COUNTA([1]BetaSolver!$A$12:$Z$1000),1)
Name Confidential.Banner: [2]Abbreviation!$L$83:$L$84
Name Conv.Qualifiers: [2]Abbreviation!$I$6:$K$20
Name Corrupt_Haver: '[2]Haver Feed_WBGov.Gov.Eff.'!#REF!
Name Country.List: '[2]Country.List'!$B$4:$B$182
Name Credit.Boom.Data: '[2]Credit.Boom.Data'!$A$5:$D$251
Name CumExpLoss: '[1]Source Tables'!$E$32:$I$52
Name CurrenciesStart: [1]Lookups!$H$59
Name Currency_Lookback: OFFSET(CurrenciesStart,0,1,COUNTA(CurrencyRecords),2)
Name CurrencyChoices: OFFSET(CurrenciesStart,0,0,COUNTA(CurrencyRecords),1)
Name CurrencyLookup: OFFSET(CurrenciesStart,0,0,COUNTA(CurrencyRecords),2)
Name CurrencyRecords: [1]Lookups!$H$59:$H$1058
Name CurrencyUsed: '[1]Model Inputs'!$D$24
Name CurrencyUsed_Buffer: [1]Buffer!$W$9
Name CurrRatingOptions: [1]Lookups!$L$67:$L$88
Name DD_Cred_Class_Actual: [1]Lookups!$B$3:$B$22
Name DD_HoldCo_OpCo: [1]Lookups!$E$38:$E$77
Name DD_Loan_Type: [1]Lookups!$E$3:$E$4
Name DD_Prec_Inc_Utilization: [1]Lookups!$J$15:$L$25
Name DefaultedExclusion: [1]Buffer!$R$3
Name E2L_Mid_: OFFSET([1]BetaSolver!$C$12,0,0,COUNTA([1]BetaSolver!$C$12:$C$65536),1)
Name E2L_Scenario_: OFFSET([1]BetaSolver!$B$12,0,0,COUNTA([1]BetaSolver!$B$12:$B$1000),1)
Name EL2Ratg: '[1]StabilityBands-4Yr'!$B$5:$C$26
Name ExpLossRate: '[1]Model Inputs'!$D$18
Name ExpLossRates: '[1]Source Tables'!$J$32:$N$52
Name F1xF2xF3.Score: '[2]Rtg.Range'!$I$5:$J$19
Name F3.Filter: [2]Abbreviation!$B$26:$B$28
Name F4.Score: '[2]Rtg.Range'!$L$5:$M$19
Name Family_DP_: '[1]Model Inputs'!$D$22
Name FamilyInDefault: '[1]Model Inputs'!$D$23
Name FDI_liabs_Haver_years: '[2]Haver Feed_IMFBOP'!$A$2:$I$2
Name FDI_liabs_Haverfeed: '[2]Haver Feed_IMFBOP'!$A$3:$I$552
Name Full.Rtg.Scale: [2]Abbreviation!$E$40:$E$60
Name GDPpercap_Haver: '[2]Haver Feed_WEO'!#REF!
Name Gov.Fi.Match: [2]F1xF2xF3.Matrix!$D$5:$R$5
Name Gov.Fi.Matrix: [2]F1xF2xF3.Matrix!$D$6:$R$20
Name High: "High"
Name Index.Conv.Qualifiers: [2]Abbreviation!$I$5
Name Input_RR_EV_: '[1]Model Inputs'!$D$19
Name InSyncWithDBLiab: [1]Backend!$B$10
Name InSyncWithDBModel: [1]Backend!$B$11
Name LGD_lookup_: '[1]Source Tables'!$J$3:$K$8
Name LiabilityInputsInputs: '[1]Liability Inputs'!$A$1:$Q$65536,'[1]Liability Inputs'!$T$1:$V$65536,'[1]Liability Inputs'!$Y$1:$Y$65536,'[1]Liability Inputs'!$AD$1:$AD$65536
Name LiabilityRequiredInputs: '[1]Liability Inputs'!$B$1:$C$65536,'[1]Liability Inputs'!$D$1:$D$65536,'[1]Liability Inputs'!$I$1:$I$65536,'[1]Liability Inputs'!$N$1:$Q$65536
Name Loss2Rtg_: '[1]Source Tables'!$B$6:$C$27
Name Low: "Low"
Name Ltd_Default_Type: [1]Buffer!$R$2:$R$4
Name MassiveLookup: '[1]StabilityBands-4Yr'!$M$2:$AA$23
Name Mids: '[1]StabilityBands-4Yr'!$C$5:$D$26
Name ModelInputsInputs: '[1]Model Inputs'!$C$3:$D$6,'[1]Model Inputs'!$C$9:$D$13,'[1]Model Inputs'!$B$28:$D$37
Name MR.Percent.List: [2]Abbreviation!$I$83:$I$104
Name No: [1]Buffer!$B$5

Sheet Table of Contents
B15: Sovereign and Supranational Rating List
B16: 46143
B19: CONTENTS BY TAB (click)
B20: Sovereign Ratings Summary
B21: Sovereign Ratings History
B22: Country Ceilings History
B23: Supranational Issuers
B24: Supranational Issuers History
B25: Short-term Ratings
B26: Definitions
B27: Disclaimer
B29: Note: Sovereign and Supranational Rating List is typically updated on Friday.

Sheet Sovereign Ratings Summary
A1: vlookup columns | B1: 1 | C1: =B1+1 -> 2 | D1: =C1+1 -> 3 | E1: =D1+1 -> 4 | F1: =E1+1 -> 5 | G1: =F1+1 -> 6 | H1: =G1+1 -> 7 | I1: =H1+1 -> 8 | J1: =I1+1 -> 9 | L1: =C1+1 -> 3 | M1: =L1+1 -> 4 | N1: =M1+1 -> 5 | O1: =N1+1 -> 6 | P1: =O1+1 -> 7 | Q1: =P1+1 -> 8 | R1: =Q1+1 -> 9
B3: Sovereign Ratings Summary
B4: 46143
D6: SOVEREIGN RATINGS | L6: COUNTRY CEILINGS
D7: FOREIGN CURRENCY | H7: LOCAL CURRENCY | L7: FOREIGN CURRENCY | P7: LOCAL CURRENCY
L8: Bonds | N8: Bank Deposits
L9: Long-term | N9: Long-term | P9: Bonds | R9: Deposits
B10: Abu Dhabi | D10: Aa2 | F10: STA | H10: Aa2 | J10: STA | L10: - | N10: - | P10: - | R10: -
B11: Albania | D11: Ba3 | F11: STA | H11: Ba3 | J11: STA | L11: Ba1 | N11: Ba2 | P11: Baa2 | R11: Baa3
B12: Andorra | D12: Baa1 | F12: POS | H12: Baa1 | J12: POS | L12: Aa3 | P12: -
B13: Angola | D13: B3 | F13: STA | H13: B3 | J13: STA | L13: B3 | N13: Caa1 | P13: B1 | R13: B2
B14: Argentina | D14: Caa1 | F14: STA | H14: Caa1 | J14: STA | L14: B2 | N14: Caa3 | P14: B1 | R14: Caa1
B15: Armenia | D15: Ba3 | F15: STA | H15: Ba3 | J15: STA | L15: Ba1 | N15: Ba1 | P15: Baa2 | R15: Baa2
B16: Aruba | D16: Baa3 | F16: POS | H16: Baa3 | J16: POS | L16: A3 | N16: Ba1 | P16: A1 | R16: Baa2
B17: Australia | D17: Aaa | F17: STA | H17: Aaa | J17: STA | L17: Aaa | N17: Aaa | P17: Aaa | R17: Aaa
B18: Austria | D18: Aa1 | F18: NEG | H18: Aa1 | J18: NEG | L18: Aaa | N18: Aaa | P18: Aaa | R18: Aaa
B19: Azerbaijan | D19: Baa3 | F19: POS | H19: Baa3 | J19: POS | L19: Baa3 | N19: Ba2 | P19: Baa1 | R19: Baa3
B20: Bahamas | D20: Ba3 | F20: STA | H20: Ba3 | J20: STA | L20: Baa3 | N20: Baa2 | P20: Baa2 | R20: Baa1
B21: Bahamas-Offshore Banks | D21: - | F21: - | H21: - | J21: - | L21: WR | N21: WR | P21: - | R21: -
B22: Bahrain | D22: B2 | F22: NEG | H22: B2 | J22: NEG | L22: Ba3 | N22: B1 | P22: Ba2 | R22: Ba3
B23: Bahrain-Offshore Banks [1] | D23: - | F23: - | H23: - | J23: - | L23: WR | N23: WR | P23: - | R23: -
B24: Bangladesh | D24: B2 | F24: NEG | H24: B2 | J24: NEG | L24: B2 | N24: Ba2 | P24: Ba3 | R24: Baa3
... B162: Zambia | D162: Caa2 | F162: POS | H162: Caa2 | J162: POS | L162: B3 | N162: Caa3 | P162: B2 | R162: Caa1
B163: [1] Wholesale Banks.
B164: [2] Senior Unsecured Rating
B166: Current as of 12/10/2015; 330pm

Sheet Sovereign Ratings History
B3: Sovereign Ratings History*
B4: 46143
D6: LONG TERM RATINGS | H6: OUTLOOK | J6: REVIEW ACTION | N6: SHORT TERM RATINGS | R6: ACTION DATE
D9: FOREIGN CURRENCY | F9: LOCAL CURRENCY | J9: FOREIGN CURRENCY | L9: LOCAL CURRENCY | N9: FOREIGN CURRENCY | P9: LOCAL CURRENCY
B10: Abu Dhabi | D10: Aa2 | F10: Aa2 | H10: STA | J10: - | L10: - | N10: P-1 | P10: P-1 | R10: 45736
B11: Abu Dhabi | D11: Aa2 | F11: Aa2 | H11: STA | J11: - | L11: - | N11: P-1 | P11: P-1 | R11: 45006
B12: Abu Dhabi | D12: Aa2 | F12: Aa2 | H12: STA | J12: - | L12: - | N12: P-1 | P12: P-1 | R12: 44320
B13: Abu Dhabi | D13: Aa2 | F13: Aa2 | H13: STA | J13: - | L13: - | N13: P-1 | P13: P-1 | R13: 42880
B14: Abu Dhabi | D14: Aa2 | F14: Aa2 | H14: NEG | J14: Confirmed | L14: Confirmed | N14: P-1 | P14: P-1 | R14: 42504
B15: Abu Dhabi | D15: Aa2 | F15: Aa2 | H15: RUR | J15: Review for Downgrade | L15: Review for Downgrade | N15: P-1 | P15: P-1 | R15: 42433
B16: Abu Dhabi | D16: Aa2 | F16: Aa2 | H16: STA | J16: - | L16: - | N16: P-1 | P16: P-1 | R16: 39274
B17: Albania | D17: Ba3 | F17: Ba3 | H17: STA | J17: - | L17: - | N17: - | P17: - | R17: 45583
B18: Albania | D18: B1 | F18: B1 | H18: POS | J18: - | L18: - | N18: - | P18: - | R18: 45401
B19: Albania | D19: B1 | F19: B1 | H19: STA | J19: - | L19: - | N19: - | P19: - | R19: 45023
B20: Albania | D20: B1 | F20: B1 | H20: STA | J20: - | L20: - | N20: - | P20: - | R20: 44337
B21: Albania | D21: B1 | F21: B1 | H21: STA | J21: - | L21: - | N21: - | P21: - | R21: 39262
... B167: Bahrain | D167: Ba1 | F167: - | H167: - | J167: - | L167: - | N167: - | P167: - | R167: 35093
B168: Bangladesh | D168: B2 | F168: B2 | H168: NEG | N168: NP | P168: NP | R168: 45614
B169: Bangladesh | D169: B1 | F169: B1 | H169: STA | N169: NP | P169: NP | R169: 45076
B170: Bangladesh | D170: Ba3 | F170: Ba3 | H170: RUR | J170: Review for Downgrade | L170: Review for Downgrade | N170: NP | P170: NP | R170: 44904
B171: Bangladesh | D171: Ba3 | F171: Ba3 | H171: STA | J171: - | L171: - | N171: NP | P171: NP | R171: 44649
B172: Bangladesh | D172: Ba3 | F172: Ba3 | H172: STA | J172: - | L172: - | N172: NP | P172: NP | R172: 40280
B173: Barbados | D173: B2 | F173: B2 | H173: STA | J173: - | L173: - | N173: - | P173: - | R173: 45761
B174: Barbados | D174: B3 | F174: B3 | H174: STA | J174: - | L174: - | N174: - | P174: - | R174: 45141
B175: Barbados | D175: Caa1 | F175: Caa1 | H175: STA | J175: - | L175: - | N175: - | P175: - | R175: 44393
B176: Barbados | D176: Caa1 | F176: Caa1 | H176: STA | J176: - | L176: - | N176: - | P176: - | R176: 43648
B177: Barbados | D177: Caa3 | F177: Caa3 | H177: STA | J177: - | L177: - | N177: - | P177: - | R177: 42803
B178: Barbados | D178: Caa1 | F178: Caa1 | H178: STA | J178: - | L178: - | N178: - | P178: - | R178: 42461
B179: Barbados | D179: B3 | F179: B3 | H179: NEG | J179: - | L179: - | N179: - | P179: - | R179: 41792
B180: Barbados | D180: Ba3 | F180: Ba3 | H180: NEG | J180: - | L180: - | N180: - | P180: - | R180: 41628
B181: Barbados | D181: Ba1 | F181: Ba1 | H181: NEG | J181: - | L181: - | N181: - | P181: - | R181: 41263
... B248: Bermuda | D248: Aa1 | F248: - | H248: - | J248: - | L248: - | N248: - | P248: - | R248: 34495
B249: Bolivia | D249: Caa3 | F249: Caa3 | H249: POS | N249: - | P249: - | R249: 46099
B250: Bolivia | D250: Ca | F250: Ca | H250: STA | N250: - | P250: - | R250: 45764
B251: Bolivia | D251: Caa3 | F251: Caa3 | H251: STA | N251: - | P251: - | R251: 45408
B252: Bolivia | D252: Caa1 | F252: Caa1 | H252: NEG | N252: - | P252: - | R252: 45107
B253: Bolivia | D253: Caa1 | F253: Caa1 | H253: RUR | J253: Review for Downgrade | L253: Review for Downgrade | N253: - | P253: - | R253: 45009
B254: Bolivia | D254: B2 | F254: B2 | H254: NEG | J254: - | L254: - | N254: - | P254: - | R254: 44469
B255: Bolivia | D255: B2 | F255: B2 | H255: STA | J255: - | L255: - | N255: - | P255: - | R255: 44096
B256: Bolivia | D256: B1 | F256: B1 | H256: NEG | J256: - | L256: - | N256: - | P256: - | R256: 43900
...

Sheet Country Ceilings History
A1: vlookup columns | B1: 1 | C1: =B1+1 -> 2 | D1: =C1+1 -> 3 | E1: =#REF!+1 -> #REF! | F1: =E1+1 -> #REF!
B3: Country Ceilings History
B4: 46143
D6: COUNTRY CEILINGS | H6: ACTION DATE
D7: FOREIGN CURRENCY | F7: LOCAL CURRENCY
D8: Bonds
D9: Long-term | F9: Bonds
B10: Abu Dhabi | D10: - | F10: - | H10: -
B11: Albania | D11: Ba1 | F11: Baa2 | H11: 45583
B12: Albania | D12: Ba2 | F12: Baa3 | H12: 45401
B13: Albania | D13: Ba2 | F13: Baa3 | H13: 45023
B14: Albania | D14: Ba2 | F14: Baa3 | H14: 44337
B15: Albania | D15: Ba2 | F15: Baa3 | H15: 44172
B16: Andorra | D16: Aa3 | F16: - | H16: 46045
B17: Andorra | D17: Aa3 | F17: - | H17: 45310
B18: Andorra | D18: A1 | F18: - | H18: 44596
B19: Angola | D19: B3 | F19: B1 | H19: 45625
B20: Angola | D20: B3 | F20: B1 | H20: 45223
B21: Angola | D21: B3 | F21: B1 | H21: 44854
B22: Angola | D22: B3 | F22: B1 | H22: 44452
... B540: Serbia | D540: Ba1 | F540: Baa2 | H540: 44172
B541: Sharjah | D541: - | F541: - | H541: -
B542: Singapore | D542: Aaa | F542: Aaa | H542: 45439
B543: Singapore | D543: Aaa | F543: Aaa | H543: 44698
B544: Singapore | D544: Aaa | F544: Aaa | H544: 44172
B545: Slovakia | D545: Aaa | F545: Aaa | H545: 45639
B546: Slovakia | D546: Aaa | F546: Aaa | H546: 45254
B547: Slovakia | D547: Aaa | F547: Aaa | H547: 44778
B548: Slovakia | D548: Aaa | F548: Aaa | H548: 44365
B549: Slovakia | D549: Aaa | F549: Aaa | H549: 44172
B550: Slovenia | D550: Aaa | F550: Aaa | H550: 46080
B551: Slovenia | D551: Aaa | F551: Aaa | H551: 45576
B552: Slovenia | D552: Aaa | F552: Aaa | H552: 44855
B553: Slovenia | D553: Aaa | F553: Aaa | H553: 44172
... B668: Zambia | D668: Caa3 | F668: Caa1 | H668: 44172
B669: [1] Wholesale Banks.
B670: [2] Senior Unsecured Rating
B672: Current as of 12/10/2015; 330pm

Sheet Supranationals Issuers
B2: Supranational Issuers
B3: 46143
D4: Long-Term
B5: Issuer | D5: Senior | G5: Short-Term | I5: Outlook
B6: African Development Bank (AfDB) | D6: Aaa | G6: P-1 | I6: STA
B7: African Export-Import Bank (Afreximbank) | D7: Baa2 [1] | E7: — | G7: P-2 | I7: STA
B8: Africa Finance Corporation (AFC) | D8: A3 | E8: — | G8: P-2 | I8: STA
B9: African Local Currency Bond Fund (ALCB) | D9: Baa1 [1] | E9: — | G9: — | I9: STA
B10: Arab Bank for Economic Development in Africa (BADEA) | D10: Aa1 | E10: — | G10: P-1 | I10: STA
B11: The Arab Energy Fund (TAEF) | D11: Aa2 | E11: — | G11: P-1 | I11: STA
B12: Asian Development Bank (ADB) | D12: Aaa | E12: — | G12: P-1 | I12: STA
B13: Asian Infrastructure Investment Bank (AIIB) | D13: Aaa | E13: — | G13: P-1 | I13: STA
B14: Banq Dev des Etats de l'Afr Cent (BDEAC) | D14: Ba3 | G14: — | I14: STA
B15: Black Sea Trade & Develop. Bank (BSTDB) | D15: Baa2 [1] | E15: — | G15: P-3 [1] | I15: STA
B16: Caribbean Development Bank (CDB) | D16: Aa1 | E16: — | G16: — | I16: STA
B17: Central Amer.Bk for Econ. Integr (CABEI) | D17: Aa3 | E17: — | G17: P-1 [1] | I17: POS
B18: CIF Capital Markets Mechanism (CCMM) | D18: Aa1 [1] | G18: — | I18: STA
B19: Corporacion Andina de Fomento (CAF) | D19: Aa3 | E19: — | G19: P-1 | I19: POS
B20: Council of Europe Develop. Bank (CEB) | D20: Aaa | E20: — | G20: P-1 | I20: STA
B21: East African Development Bank (EADB) | D21: Baa3 | E21: — | G21: — | I21: STA
B22: ECOWAS Bank For Investment and Development (EBID) | D22: B2[1] | E22: — | G22: — | I22: STA
B23: EFSF (European Financial Stability Facility) | D23: Aaa | E23: — | G23: (P)P-1 | I23: NEG
B24: Emerging Africa Infrastructure Fund (EAIF) | D24: A2 [1] | E24: — | G24: — | I24: STA
B25: Eurasian Development Bank (EDB) | D25: WR | E25: — | G25: WR | I25: RWR
B26: Eurofima | D26: Aa2 | E26: — | G26: P-1 | I26: STA
B27: European Bank for Rec. & Dev. (EBRD) | D27: Aaa | E27: — | G27: P-1 [1] | I27: STA
B28: European Investment Bank (EIB) | D28: Aaa | E28: — | G28: P-1 | I28: STA
B29: European Investment Fund (EIF) | D29: Aaa [1] | E29: — | G29: — | I29: STA
B30: European Stability Mechanism (ESM) | D30: Aaa | E30: — | G30: P-1 | I30: STA
... B35: Global Climate Partnership Fund (GCPF) | D35: A3 [1] | E35: — | G35: — | I35: STA
B36: Global Gender-Smart Fund S.A., SICAV-SIF (GGSF) | D36: A3 | G36: — | I36: STA
B37: GuarantCo | D37: A1 | E37: — | G37: — | I37: STA
B38: Gulf Investment Corporation G.S.C. (GIC) | D38: A2 | E38: — | G38: P-1 | I38: STA
B39: International Bank for Economic Co-operation (IBEC) | D39: WR | E39: — | G39: — | I39: RWR
B40: IBRD (World Bank) | D40: Aaa | E40: — | G40: P-1 | I40: STA
B41: Int'l Fin. Facil. for Education (IFFEd) | D41: Aaa [1] | G41: — | I41: STA
B42: Int'l Fin. Facil. for Immunisation (IFFIm) | D42: Aa1 | E42: — | G42: P-1 [1] | I42: STA
B43: Inter-American Development Bank (IADB) | D43: Aaa | E43: — | G43: P-1 [1] | I43: STA
B44: Inter-American Investment Corp (IDB) | D44: Aa1 [1] | E44: — | G44: P-1 [1] | I44: STA
B45: International Development Association (IDA) | D45: Aaa [1] | E45: — | G45: P-1 | I45: STA
...

Sheet Supranationals Issuers History
B2: Supranational Issuers History
B3: 46143
D4: Long-Term
B6: Issuer | D6: Senior | G6: Short Term | I6: Outlook | K6: Rating Date
B7: African Development Bank (AfDB) | D7: Aaa | E7: - | G7: P-1 | I7: STA | K7: 45926
B8: African Development Bank (AfDB) | D8: Aaa | E8: - | G8: P-1 | I8: STA | K8: 45218
B9: African Development Bank (AfDB) | D9: Aaa | E9: - | G9: P-1 | I9: STA | K9: 44497
B10: African Development Bank (AfDB) | D10: Aaa | E10: - | G10: P-1 | I10: STA | K10: 10/25/2019
B11: African Development Bank (AfDB) | D11: Aaa | E11: - | G11: P-1 | I11: STA | K11: 08/25/2017
B12: African Development Bank (AfDB) | D12: Aaa | E12: - | G12: P-1 | I12: STA | K12: 08/29/2014
B13: African Development Bank (AfDB) | D13: Aaa | E13: - | G13: P-1 | I13: STA | K13: 40418
B14: African Development Bank (AfDB) | D14: Aaa | E14: - | G14: P-1 | I14: STA | K14: 11/15/2003
B15: African Development Bank (AfDB) | D15: Aaa | E15: - | G15: P-1 | I15: - | K15: 03/15/2000
B16: African Development Bank (AfDB) | D16: Aaa | E16: - | G16: - | I16: - | K16: 34712
B17: African Development Bank (AfDB) | D17: Aaa | E17: - | G17: - | I17: - | K17: 12/21/1994
B18: African Development Bank (AfDB) | D18: Aaa | E18: - | G18: - | I18: - | K18: 03/23/1984
B19: African Export-Import Bank (Afreximbank) | D19: Baa2 | E19: - | G19: P-2 | I19: STA | K19: 45839
B20: African Export-Import Bank (Afreximbank) | D20: Baa1 | E20: - | G20: P-2 | I20: NEG | K20: 45341
B21: African Export-Import Bank (Afreximbank) | D21: Baa1 | E21: - | G21: - | I21: STA | K21: 44376
B22: African Export-Import Bank (Afreximbank) | D22: Baa1 | E22: - | G22: - | I22: STA | K22: 08/09/2019
B23: African Export-Import Bank (Afreximbank) | D23: Baa1 | E23: - | G23: - | I23: STA | K23: 01/23/2017
B24: African Export-Import Bank (Afreximbank) | D24: Baa2 | E24: - | G24: - | I24: STA | K24: 07/22/2015
B25: African Export-Import Bank (Afreximbank) | D25: Baa2 | E25: - | G25: - | I25: NEG | K25: 09/11/2014
B26: African Export-Import Bank (Afreximbank) | D26: Baa2 | E26: - | G26: - | I26: NEG | K26: 03/05/2014
B27: African Export-Import Bank (Afreximbank) | D27: Baa2 | E27: - | G27: - | I27: STA | K27: 07/25/2011
B28: African Export-Import Bank (Afreximbank) | D28: Baa2 | E28: - | G28: - | I28: STA | K28: 05/28/2010
B29: Africa Finance Corporation (AFC) | D29: A3 | E29: - | G29: P-2 | I29: STA | K29: 45559
B30: Africa Finance Corporation (AFC) | D30: A3 | E30: - | G30: P-2 | I30: NEG | K30: 44984
B31: Africa Finance Corporation (AFC) | D31: A3 | E31: - | G31: P-2 | I31: STA | K31: 44349
B32: Africa Finance Corporation (AFC) | D32: A3 | E32: - | G32: P-2 | I32: NEG | K32: 05/05/2020
B33: Africa Finance Corporation (AFC) | D33: A3 | E33: - | G33: P-2 | I33: STA | K33: 12/13/2018
B34: Africa Finance Corporation (AFC) | D34: A3 | E34: - | G34: P-2 | I34: STA | K34: 05/06/2015
B35: Africa Finance Corporation (AFC) | D35: (P)A3 | E35: - | G35: P-2 | I35: STA | K35: 04/15/2015
B36: Africa Finance Corporation (AFC) | D36: A3 | E36: - | G36: P-2 | I36: STA | K36: 03/03/2014
B37: African Local Currency Bond Fund (ALCB) | D37: Baa1 | E37: - | G37: - | I37: STA | K37: 45478
B38: African Local Currency Bond Fund (ALCB) | D38: Baa1 | E38: - | G38: - | I38: STA | K38: 45065
B39: African Local Currency Bond Fund (ALCB) | D39: Baa2 | E39: - | G39: - | I39: STA | K39: 44344
B40: African Local Currency Bond Fund (ALCB) | D40: Baa2 | E40: - | G40: - | I40: STA | K40: 05/21/2019
B41: Arab Bank for Economic Development in Africa (BADEA) | D41: Aa1 | E41: - | G41: P-1 | I41: STA | K41: 45825
B42: Arab Bank for Economic Development in Africa (BADEA) | D42: Aa1 | E42: - | G42: - | I42: STA | K42: 45433
...

Sheet Short-term Ratings
A1: vlookup columns | B1: 1 | C1: =B1+1 -> 2 | D1: =#REF!+1 -> #REF! | E1: =#REF!+1 -> #REF!
B3: Sovereign: Short-Term Ratings
B4: 46143
D6: Short-term Foreign Currency
D7: RATINGS
B9: Abu Dhabi | D9: P-1
B10: Albania | D10: --
B11: Andorra | D11: --
B12: Angola | D12: NP
B13: Argentina | D13: --
B14: Armenia | D14: --
B15: Aruba | D15: --
B16: Australia | D16: --
B17: Austria | D17: P-1
B18: Azerbaijan | D18: --
B19: Bahamas | D19: --
B20: Bahamas-Offshore Banks | D20: --
... B163: Zambia | D163: --
B164: [1] Wholesale Banks.
B165: [2] Senior Unsecured Rating | D165: Current as of 12/16/2015; 600pm EST

Sheet Definitions and Notes
B2: Definitions
B4: Local-Currency Sovereign Ratings reflect the sovereign's capacity and willingness to obtain local-currency to repay its local-currency financial obligations on a timely basis.
B6: Foreign-Currency Sovereign Ratings reflect the sovereign's capacity and willingness to mobilize foreign exchange to repay its foreign-currency denominated financial obligations on a timely basis.
B8: Country Ceilings reflect the non-diversifiable risk incurred by investors in any sovereign credit environment. Country risk arises because non-sovereign issuers are typically subject to a country’s prevailing economic, institutional, financial and political environment. Local currency country ceilings are relevant to obligations denominated in the currency of the country of domicile or origination, and foreign currency country ceilings are relevant to obligations denominated in a different currency.
B11: Notes
B13: 1. Note that the rating history does not include rating affirmations.
B14: 2. Note that the rating history only captures rating outlooks starting in late 2003, when Moody’s started to record outlooks in a database.
B15: 3. For further details on various rating symbols, rating scales and other ratings-related definitions, please see Moody’s Rating Symbols and Definitions.

Sheet Disclaimer

Sheet Rtg List
A1: Index.Column | B1: =COLUMN() -> 2 | C1: =COLUMN() -> 3 | D1: =COLUMN() -> 4 | E1: =COLUMN() -> 5 | F1: =COLUMN() -> 6 | G1: =COLUMN() -> 7 | H1: =COLUMN() -> 8 | I1: =COLUMN() -> 9 | ... V1: =COLUMN() -> 22
A2: Updating sheet for Sov Scorecard
A3: Gov. Bond Rating | B3: VLookUp.Name | C3: Gov. Bond Rating | H3: FC Ceilings | K3: LC Ceilings
A4: Country.List.Name | C4: FC | D4: Outlook | E4: LC | F4: Outlook | H4: Bond | I4: Deposits | K4: Bond | L4: Deposits
A5: Albania | B5: Albania | C5: =IFERROR(VLOOKUP($B5,'Sovereign Ratings Summary'!$B$10:$R$309,3,FALSE),"--") -> Ba3 | D5: =IFERROR(VLOOKUP($B5,'Sovereign Ratings Summary'!$B$10:$R$309,5,FALSE),"--") -> STA | E5: =IFERROR(VLOOKUP($B5,'Sovereign Ratings Summary'!$B$10:$R$309,7,FALSE),"--") -> Ba3 | F5: =IFERROR(VLOOKUP($B5,'Sovereign Ratings Summary'!$B$10:$R$309,9,FALSE),"--") -> STA | H5: =IFERROR(VLOOKUP($B5,'Sovereign Ratings Summary'!$B$10:$R$309,11,FALSE),"--") -> Ba1 | I5: =IFERROR(VLOOKUP($B5,'Sovereign Ratings Summary'!$B$10:$R$309,13,FALSE),"--") -> Ba2 | K5: =IFERROR(VLOOKUP($B5,'Sovereign Ratings Summary'!$B$10:$R$309,15,FALSE),"--") -> Baa2 | L5: =IFERROR(VLOOKUP($B5,'Sovereign Ratings Summary'!$B$10:$R$309,17,FALSE),"--") -> Baa3 | N5: =""
A6: Angola | B6: Angola | C6: =IFERROR(VLOOKUP($B6,'Sovereign Ratings Summary'!$B$10:$R$309,3,FALSE),"--") -> B3 | D6: =IFERROR(VLOOKUP($B6,'Sovereign Ratings Summary'!$B$10:$R$309,5,FALSE),"--") -> STA | E6: =IFERROR(VLOOKUP($B6,'Sovereign Ratings Summary'!$B$10:$R$309,7,FALSE),"--") -> B3 | F6: =IFERROR(VLOOKUP($B6,'Sovereign Ratings Summary'!$B$10:$R$309,9,FALSE),"--") -> STA | H6: =IFERROR(VLOOKUP($B6,'Sovereign Ratings Summary'!$B$10:$R$309,11,FALSE),"--") -> B3 | I6: =IFERROR(VLOOKUP($B6,'Sovereign Ratings Summary'!$B$10:$R$309,13,FALSE),"--") -> Caa1 | K6: =IFERROR(VLOOKUP($B6,'Sovereign Ratings Summary'!$B$10:$R$309,15,FALSE),"--") -> B1 | L6: =IFERROR(VLOOKUP($B6,'Sovereign Ratings Summary'!$B$10:$R$309,17,FALSE),"--") -> B2 | N6: =""
A7: Argentina | B7: Argentina | C7: =IFERROR(VLOOKUP($B7,'Sovereign Ratings Summary'!$B$10:$R$309,3,FALSE),"--") -> Caa1 | D7: =IFERROR(VLOOKUP($B7,'Sovereign Ratings Summary'!$B$10:$R$309,5,FALSE),"--") -> STA | E7: =IFERROR(VLOOKUP($B7,'Sovereign Ratings Summary'!$B$10:$R$309,7,FALSE),"--") -> Caa1 | F7: =IFERROR(VLOOKUP($B7,'Sovereign Ratings Summary'!$B$10:$R$309,9,FALSE),"--") -> STA | H7: =IFERROR(VLOOKUP($B7,'Sovereign Ratings Summary'!$B$10:$R$309,11,FALSE),"--") -> B2 | I7: =IFERROR(VLOOKUP($B7,'Sovereign Ratings Summary'!$B$10:$R$309,13,FALSE),"--") -> Caa3 | K7: =IFERROR(VLOOKUP($B7,'Sovereign Ratings Summary'!$B$10:$R$309,15,FALSE),"--") -> B1 | L7: =IFERROR(VLOOKUP($B7,'Sovereign Ratings Summary'!$B$10:$R$309,17,FALSE),"--") -> Caa1 | N7: =""
A8: Armenia | B8: Armenia | C8: =IFERROR(VLOOKUP($B8,'Sovereign Ratings Summary'!$B$10:$R$309,3,FALSE),"--") -> Ba3 | D8: =IFERROR(VLOOKUP($B8,'Sovereign Ratings Summary'!$B$10:$R$309,5,FALSE),"--") -> STA | E8: =IFERROR(VLOOKUP($B8,'Sovereign Ratings Summary'!$B$10:$R$309,7,FALSE),"--") -> Ba3 | F8: =IFERROR(VLOOKUP($B8,'Sovereign Ratings Summary'!$B$10:$R$309,9,FALSE),"--") -> STA | H8: =IFERROR(VLOOKUP($B8,'Sovereign Ratings Summary'!$B$10:$R$309,11,FALSE),"--") -> Ba1 | I8: =IFERROR(VLOOKUP($B8,'Sovereign Ratings Summary'!$B$10:$R$309,13,FALSE),"--") -> Ba1 | K8: =IFERROR(VLOOKUP($B8,'Sovereign Ratings Summary'!$B$10:$R$309,15,FALSE),"--") -> Baa2 | L8: =IFERROR(VLOOKUP($B8,'Sovereign Ratings Summary'!$B$10:$R$309,17,FALSE),"--") -> Baa2 | N8: =""
A9: Australia | B9: Australia | C9: =IFERROR(VLOOKUP($B9,'Sovereign Ratings Summary'!$B$10:$R$309,3,FALSE),"--") -> Aaa | D9: =IFERROR(VLOOKUP($B9,'Sovereign Ratings Summary'!$B$10:$R$309,5,FALSE),"--") -> STA | E9: =IFERROR(VLOOKUP($B9,'Sovereign Ratings Summary'!$B$10:$R$309,7,FALSE),"--") -> Aaa | F9: =IFERROR(VLOOKUP($B9,'Sovereign Ratings Summary'!$B$10:$R$309,9,FALSE),"--") -> STA | H9: =IFERROR(VLOOKUP($B9,'Sovereign Ratings Summary'!$B$10:$R$309,11,FALSE),"--") -> Aaa | I9: =IFERROR(VLOOKUP($B9,'Sovereign Ratings Summary'!$B$10:$R$309,13,FALSE),"--") -> Aaa | K9: =IFERROR(VLOOKUP($B9,'Sovereign Ratings Summary'!$B$10:$R$309,15,FALSE),"--") -> Aaa | L9: =IFERROR(VLOOKUP($B9,'Sovereign Ratings Summary'!$B$10:$R$309,17,FALSE),"--") -> Aaa | N9: =""
A10: Austria | B10: Austria | C10: =IFERROR(VLOOKUP($B10,'Sovereign Ratings Summary'!$B$10:$R$309,3,FALSE),"--") -> Aa1 | D10: =IFERROR(VLOOKUP($B10,'Sovereign Ratings Summary'!$B$10:$R$309,5,FALSE),"--") -> NEG | E10: =IFERROR(VLOOKUP($B10,'Sovereign Ratings Summary'!$B$10:$R$309,7,FALSE),"--") -> Aa1 | F10: =IFERROR(VLOOKUP($B10,'Sovereign Ratings Summary'!$B$10:$R$309,9,FALSE),"--") -> NEG | H10: =IFERROR(VLOOKUP($B10,'Sovereign Ratings Summary'!$B$10:$R$309,11,FALSE),"--") -> Aaa | I10: =IFERROR(VLOOKUP($B10,'Sovereign Ratings Summary'!$B$10:$R$309,13,FALSE),"--") -> Aaa | K10: =IFERROR(VLOOKUP($B10,'Sovereign Ratings Summary'!$B$10:$R$309,15,FALSE),"--") -> Aaa | L10: =IFERROR(VLOOKUP($B10,'Sovereign Ratings Summary'!$B$10:$R$309,17,FALSE),"--") -> Aaa | N10: =""
A11: Azerbaijan | B11: Azerbaijan | C11: =IFERROR(VLOOKUP($B11,'Sovereign Ratings Summary'!$B$10:$R$309,3,FALSE),"--") -> Baa3 | D11: =IFERROR(VLOOKUP($B11,'Sovereign Ratings Summary'!$B$10:$R$309,5,FALSE),"--") -> POS | E11: =IFERROR(VLOOKUP($B11,'Sovereign Ratings Summary'!$B$10:$R$309,7,FALSE),"--") -> Baa3 | F11: =IFERROR(VLOOKUP($B11,'Sovereign Ratings Summary'!$B$10:$R$309,9,FALSE),"--") -> POS | H11: =IFERROR(VLOOKUP($B11,'Sovereign Ratings Summary'!$B$10:$R$309,11,FALSE),"--") -> Baa3 | I11: =IFERROR(VLOOKUP($B11,'Sovereign Ratings Summary'!$B$10:$R$309,13,FALSE),"--") -> Ba2 | K11: =IFERROR(VLOOKUP($B11,'Sovereign Ratings Summary'!$B$10:$R$309,15,FALSE),"--") -> Baa1 | L11: =IFERROR(VLOOKUP($B11,'Sovereign Ratings Summary'!$B$10:$R$309,17,FALSE),"--") -> Baa3 | N11: =""
A12: Bahamas | B12: Bahamas | C12: =IFERROR(VLOOKUP($B12,'Sovereign Ratings Summary'!$B$10:$R$309,3,FALSE),"--") -> Ba3 | D12: =IFERROR(VLOOKUP($B12,'Sovereign Ratings Summary'!$B$10:$R$309,5,FALSE),"--") -> STA | E12: =IFERROR(VLOOKUP($B12,'Sovereign Ratings Summary'!$B$10:$R$309,7,FALSE),"--") -> Ba3 | F12: =IFERROR(VLOOKUP($B12,'Sovereign Ratings Summary'!$B$10:$R$309,9,FALSE),"--") -> STA | H12: =IFERROR(VLOOKUP($B12,'Sovereign Ratings Summary'!$B$10:$R$309,11,FALSE),"--") -> Baa3 | I12: =IFERROR(VLOOKUP($B12,'Sovereign Ratings Summary'!$B$10:$R$309,13,FALSE),"--") -> Baa2 | K12: =IFERROR(VLOOKUP($B12,'Sovereign Ratings Summary'!$B$10:$R$309,15,FALSE),"--") -> Baa2 | L12: =IFERROR(VLOOKUP($B12,'Sovereign Ratings Summary'!$B$10:$R$309,17,FALSE),"--") -> Baa1 | N12: =""
A13: Bahrain | B13: Bahrain | C13: =IFERROR(VLOOKUP($B13,'Sovereign Ratings Summary'!$B$10:$R$309,3,FALSE),"--") -> B2 | D13: =IFERROR(VLOOKUP($B13,'Sovereign Ratings Summary'!$B$10:$R$309,5,FALSE),"--") -> NEG | E13: =IFERROR(VLOOKUP($B13,'Sovereign Ratings Summary'!$B$10:$R$309,7,FALSE),"--") -> B2 | F13: =IFERROR(VLOOKUP($B13,'Sovereign Ratings Summary'!$B$10:$R$309,9,FALSE),"--") -> NEG | H13: =IFERROR(VLOOKUP($B13,'Sovereign Ratings Summary'!$B$10:$R$309,11,FALSE),"--") -> Ba3 | I13: =IFERROR(VLOOKUP($B13,'Sovereign Ratings Summary'!$B$10:$R$309,13,FALSE),"--") -> B1 | K13: =IFERROR(VLOOKUP($B13,'Sovereign Ratings Summary'!$B$10:$R$309,15,FALSE),"--") -> Ba2 | L13: =IFERROR(VLOOKUP($B13,'Sovereign Ratings Summary'!$B$10:$R$309,17,FALSE),"--") -> Ba3 | N13: =""
A14: Bangladesh | B14: Bangladesh | C14: =IFERROR(VLOOKUP($B14,'Sovereign Ratings Summary'!$B$10:$R$309,3,FALSE),"--") -> B2 | D14: =IFERROR(VLOOKUP($B14,'Sovereign Ratings Summary'!$B$10:$R$309,5,FALSE),"--") -> NEG | E14: =IFERROR(VLOOKUP($B14,'Sovereign Ratings Summary'!$B$10:$R$309,7,FALSE),"--") -> B2 | F14: =IFERROR(VLOOKUP($B14,'Sovereign Ratings Summary'!$B$10:$R$309,9,FALSE),"--") -> NEG | H14: =IFERROR(VLOOKUP($B14,'Sovereign Ratings Summary'!$B$10:$R$309,11,FALSE),"--") -> B2 | I14: =IFERROR(VLOOKUP($B14,'Sovereign Ratings Summary'!$B$10:$R$309,13,FALSE),"--") -> Ba2 | K14: =IFERROR(VLOOKUP($B14,'Sovereign Ratings Summary'!$B$10:$R$309,15,FALSE),"--") -> Ba3 | L14: =IFERROR(VLOOKUP($B14,'Sovereign Ratings Summary'!$B$10:$R$309,17,FALSE),"--") -> Baa3 | N14: =""
A15: Barbados | B15: Barbados | C15: =IFERROR(VLOOKUP($B15,'Sovereign Ratings Summary'!$B$10:$R$309,3,FALSE),"--") -> B2 | D15: =IFERROR(VLOOKUP($B15,'Sovereign Ratings Summary'!$B$10:$R$309,5,FALSE),"--") -> STA | E15: =IFERROR(VLOOKUP($B15,'Sovereign Ratings Summary'!$B$10:$R$309,7,FALSE),"--") -> B2 | F15: =IFERROR(VLOOKUP($B15,'Sovereign Ratings Summary'!$B$10:$R$309,9,FALSE),"--") -> STA | H15: =IFERROR(VLOOKUP($B15,'Sovereign Ratings Summary'!$B$10:$R$309,11,FALSE),"--") -> B1 | I15: =IFERROR(VLOOKUP($B15,'Sovereign Ratings Summary'!$B$10:$R$309,13,FALSE),"--") -> B3 | K15: =IFERROR(VLOOKUP($B15,'Sovereign Ratings Summary'!$B$10:$R$309,15,FALSE),"--") -> Ba2 | L15: =IFERROR(VLOOKUP($B15,'Sovereign Ratings Summary'!$B$10:$R$309,17,FALSE),"--") -> B1 | N15: =""
A16: Belarus | B16: Belarus | C16: =IFERROR(VLOOKUP($B16,'Sovereign Ratings Summary'!$B$10:$R$309,3,FALSE),"--") -> C | D16: =IFERROR(VLOOKUP($B16,'Sovereign Ratings Summary'!$B$10:$R$309,5,FALSE),"--") -> STA | E16: =IFERROR(VLOOKUP($B16,'Sovereign Ratings Summary'!$B$10:$R$309,7,FALSE),"--") -> C | F16: =IFERROR(VLOOKUP($B16,'Sovereign Ratings Summary'!$B$10:$R$309,9,FALSE),"--") -> STA | H16: =IFERROR(VLOOKUP($B16,'Sovereign Ratings Summary'!$B$10:$R$309,11,FALSE),"--") -> Ca | I16: =IFERROR(VLOOKUP($B16,'Sovereign Ratings Summary'!$B$10:$R$309,13,FALSE),"--") -> B3 | K16: =IFERROR(VLOOKUP($B16,'Sovereign Ratings Summary'!$B$10:$R$309,15,FALSE),"--") -> Caa3 | L16: =IFERROR(VLOOKUP($B16,'Sovereign Ratings Summary'!$B$10:$R$309,17,FALSE),"--") -> B2 | N16: =""
... A19: Bermuda | B19: Bermuda | C19: =IFERROR(VLOOKUP($B19,'Sovereign Ratings Summary'!$B$10:$R$309,3,FALSE),"--") -> A2 | D19: =IFERROR(VLOOKUP($B19,'Sovereign Ratings Summary'!$B$10:$R$309,5,FALSE),"--") -> STA | E19: =IFERROR(VLOOKUP($B19,'Sovereign Ratings Summary'!$B$10:$R$309,7,FALSE),"--") -> A2 | F19: =IFERROR(VLOOKUP($B19,'Sovereign Ratings Summary'!$B$10:$R$309,9,FALSE),"--") -> STA | H19: =IFERROR(VLOOKUP($B19,'Sovereign Ratings Summary'!$B$10:$R$309,11,FALSE),"--") -> Aaa | I19: =IFERROR(VLOOKUP($B19,'Sovereign Ratings Summary'!$B$10:$R$309,13,FALSE),"--") -> Aaa | K19: =IFERROR(VLOOKUP($B19,'Sovereign Ratings Summary'!$B$10:$R$309,15,FALSE),"--") -> Aaa | L19: =IFERROR(VLOOKUP($B19,'Sovereign Ratings Summary'!$B$10:$R$309,17,FALSE),"--") -> Aaa | N19: =""
A20: Bolivia | B20: Bolivia | C20: =IFERROR(VLOOKUP($B20,'Sovereign Ratings Summary'!$B$10:$R$309,3,FALSE),"--") -> Caa3 | D20: =IFERROR(VLOOKUP($B20,'Sovereign Ratings Summary'!$B$10:$R$309,5,FALSE),"--") -> POS | E20: =IFERROR(VLOOKUP($B20,'Sovereign Ratings Summary'!$B$10:$R$309,7,FALSE),"--") -> Caa3 | F20: =IFERROR(VLOOKUP($B20,'Sovereign Ratings Summary'!$B$10:$R$309,9,FALSE),"--") -> POS | H20: =IFERROR(VLOOKUP($B20,'Sovereign Ratings Summary'!$B$10:$R$309,11,FALSE),"--") -> Caa2 | I20: =IFERROR(VLOOKUP($B20,'Sovereign Ratings Summary'!$B$10:$R$309,13,FALSE),"--") -> B2 | K20: =IFERROR(VLOOKUP($B20,'Sovereign Ratings Summary'!$B$10:$R$309,15,FALSE),"--") -> Caa1 | L20: =IFERROR(VLOOKUP($B20,'Sovereign Ratings Summary'!$B$10:$R$309,17,FALSE),"--") -> Ba3
A21: Bosnia and Herzegovina | B21: Bosnia and Herzegovina | C21: =IFERROR(VLOOKUP($B21,'Sovereign Ratings Summary'!$B$10:$R$309,3,FALSE),"--") -> B3 | D21: =IFERROR(VLOOKUP($B21,'Sovereign Ratings Summary'!$B$10:$R$309,5,FALSE),"--") -> STA | E21: =IFERROR(VLOOKUP($B21,'Sovereign Ratings Summary'!$B$10:$R$309,7,FALSE),"--") -> B3 | F21: =IFERROR(VLOOKUP($B21,'Sovereign Ratings Summary'!$B$10:$R$309,9,FALSE),"--") -> STA | H21: =IFERROR(VLOOKUP($B21,'Sovereign Ratings Summary'!$B$10:$R$309,11,FALSE),"--") -> B3 | I21: =IFERROR(VLOOKUP($B21,'Sovereign Ratings Summary'!$B$10:$R$309,13,FALSE),"--") -> B3 | K21: =IFERROR(VLOOKUP($B21,'Sovereign Ratings Summary'!$B$10:$R$309,15,FALSE),"--") -> B1 | L21: =IFERROR(VLOOKUP($B21,'Sovereign Ratings Summary'!$B$10:$R$309,17,FALSE),"--") -> B1 | N21: =""
A22: Botswana | B22: Botswana | C22: =IFERROR(VLOOKUP($B22,'Sovereign Ratings Summary'!$B$10:$R$309,3,FALSE),"--") -> Baa1 | D22: =IFERROR(VLOOKUP($B22,'Sovereign Ratings Summary'!$B$10:$R$309,5,FALSE),"--") -> NEG | E22: =IFERROR(VLOOKUP($B22,'Sovereign Ratings Summary'!$B$10:$R$309,7,FALSE),"--") -> Baa1 | F22: =IFERROR(VLOOKUP($B22,'Sovereign Ratings Summary'!$B$10:$R$309,9,FALSE),"--") -> NEG | H22: =IFERROR(VLOOKUP($B22,'Sovereign Ratings Summary'!$B$10:$R$309,11,FALSE),"--") -> A2 | I22: =IFERROR(VLOOKUP($B22,'Sovereign Ratings Summary'!$B$10:$R$309,13,FALSE),"--") -> Aa3 | K22: =IFERROR(VLOOKUP($B22,'Sovereign Ratings Summary'!$B$10:$R$309,15,FALSE),"--") -> A1 | L22: =IFERROR(VLOOKUP($B22,'Sovereign Ratings Summary'!$B$10:$R$309,17,FALSE),"--") -> Aa2 | N22: =""
A23: Brazil | B23: Brazil | C23: =IFERROR(VLOOKUP($B23,'Sovereign Ratings Summary'!$B$10:$R$309,3,FALSE),"--") -> Ba1 | D23: =IFERROR(VLOOKUP($B23,'Sovereign Ratings Summary'!$B$10:$R$309,5,FALSE),"--") -> STA | E23: =IFERROR(VLOOKUP($B23,'Sovereign Ratings Summary'!$B$10:$R$309,7,FALSE),"--") -> Ba1 | F23: =IFERROR(VLOOKUP($B23,'Sovereign Ratings Summary'!$B$10:$R$309,9,FALSE),"--") -> STA | H23: =IFERROR(VLOOKUP($B23,'Sovereign Ratings Summary'!$B$10:$R$309,11,FALSE),"--") -> Baa1 | I23: =IFERROR(VLOOKUP($B23,'Sovereign Ratings Summary'!$B$10:$R$309,13,FALSE),"--") -> Baa2 | K23: =IFERROR(VLOOKUP($B23,'Sovereign Ratings Summary'!$B$10:$R$309,15,FALSE),"--") -> A3 | L23: =IFERROR(VLOOKUP($B23,'Sovereign Ratings Summary'!$B$10:$R$309,17,FALSE),"--") -> Baa1 | N23: =""
A24: Bulgaria | B24: Bulgaria | C24: =IFERROR(VLOOKUP($B24,'Sovereign Ratings Summary'!$B$10:$R$309,3,FALSE),"--") -> Baa1 | D24: =IFERROR(VLOOKUP($B24,'Sovereign Ratings Summary'!$B$10:$R$309,5,FALSE),"--") -> STA | E24: =IFERROR(VLOOKUP($B24,'Sovereign Ratings Summary'!$B$10:$R$309,7,FALSE),"--") -> Baa1 | F24: =IFERROR(VLOOKUP($B24,'Sovereign Ratings Summary'!$B$10:$R$309,9,FALSE),"--") -> STA | H24: =IFERROR(VLOOKUP($B24,'Sovereign Ratings Summary'!$B$10:$R$309,11,FALSE),"--") -> Aa1 | I24: =IFERROR(VLOOKUP($B24,'Sovereign Ratings Summary'!$B$10:$R$309,13,FALSE),"--") -> Aa2 | K24: =IFERROR(VLOOKUP($B24,'Sovereign Ratings Summary'!$B$10:$R$309,15,FALSE),"--") -> Aa1 | L24: =IFERROR(VLOOKUP($B24,'Sovereign Ratings Summary'!$B$10:$R$309,17,FALSE),"--") -> Aa2 | N24: =""
A25: Cambodia | B25: Cambodia | C25: =IFERROR(VLOOKUP($B25,'Sovereign Ratings Summary'!$B$10:$R$309,3,FALSE),"--") -> B2 | D25: =IFERROR(VLOOKUP($B25,'Sovereign Ratings Summary'!$B$10:$R$309,5,FALSE),"--") -> STA | E25: =IFERROR(VLOOKUP($B25,'Sovereign Ratings Summary'!$B$10:$R$309,7,FALSE),"--") -> B2 | F25: =IFERROR(VLOOKUP($B25,'Sovereign Ratings Summary'!$B$10:$R$309,9,FALSE),"--") -> STA | H25: =IFERROR(VLOOKUP($B25,'Sovereign Ratings Summary'!$B$10:$R$309,11,FALSE),"--") -> B1 | I25: =IFERROR(VLOOKUP($B25,'Sovereign Ratings Summary'!$B$10:$R$309,13,FALSE),"--") -> B1 | K25: =IFERROR(VLOOKUP($B25,'Sovereign Ratings Summary'!$B$10:$R$309,15,FALSE),"--") -> Ba3 | L25: =IFERROR(VLOOKUP($B25,'Sovereign Ratings Summary'!$B$10:$R$309,17,FALSE),"--") -> Ba3 | N25: =""
A26: Canada | B26: Canada | C26: =IFERROR(VLOOKUP($B26,'Sovereign Ratings Summary'!$B$10:$R$309,3,FALSE),"--") -> Aaa | D26: =IFERROR(VLOOKUP($B26,'Sovereign Ratings Summary'!$B$10:$R$309,5,FALSE),"--") -> STA | E26: =IFERROR(VLOOKUP($B26,'Sovereign Ratings Summary'!$B$10:$R$309,7,FALSE),"--") -> Aaa | F26: =IFERROR(VLOOKUP($B26,'Sovereign Ratings Summary'!$B$10:$R$309,9,FALSE),"--") -> STA | H26: =IFERROR(VLOOKUP($B26,'Sovereign Ratings Summary'!$B$10:$R$309,11,FALSE),"--") -> Aaa | I26: =IFERROR(VLOOKUP($B26,'Sovereign Ratings Summary'!$B$10:$R$309,13,FALSE),"--") -> Aaa | K26: =IFERROR(VLOOKUP($B26,'Sovereign Ratings Summary'!$B$10:$R$309,15,FALSE),"--") -> Aaa | L26: =IFERROR(VLOOKUP($B26,'Sovereign Ratings Summary'!$B$10:$R$309,17,FALSE),"--") -> Aaa | N26: =""
A27: Cayman Islands | B27: Cayman Islands | C27: =IFERROR(VLOOKUP($B27,'Sovereign Ratings Summary'!$B$10:$R$309,3,FALSE),"--") -> Aa3 | D27: =IFERROR(VLOOKUP($B27,'Sovereign Ratings Summary'!$B$10:$R$309,5,FALSE),"--") -> STA | E27: =IFERROR(VLOOKUP($B27,'Sovereign Ratings Summary'!$B$10:$R$309,7,FALSE),"--") -> Aa3 | F27: =IFERROR(VLOOKUP($B27,'Sovereign Ratings Summary'!$B$10:$R$309,9,FALSE),"--") -> STA | H27: =IFERROR(VLOOKUP($B27,'Sovereign Ratings Summary'!$B$10:$R$309,11,FALSE),"--") -> Aaa | I27: =IFERROR(VLOOKUP($B27,'Sovereign Ratings Summary'!$B$10:$R$309,13,FALSE),"--") -> Aaa | K27: =IFERROR(VLOOKUP($B27,'Sovereign Ratings Summary'!$B$10:$R$309,15,FALSE),"--") -> Aaa | L27: =IFERROR(VLOOKUP($B27,'Sovereign Ratings Summary'!$B$10:$R$309,17,FALSE),"--") -> Aaa | N27: =""
A28: Chile | B28: Chile | C28: =IFERROR(VLOOKUP($B28,'Sovereign Ratings Summary'!$B$10:$R$309,3,FALSE),"--") -> A2 | D28: =IFERROR(VLOOKUP($B28,'Sovereign Ratings Summary'!$B$10:$R$309,5,FALSE),"--") -> STA | E28: =IFERROR(VLOOKUP($B28,'Sovereign Ratings Summary'!$B$10:$R$309,7,FALSE),"--") -> A2 | F28: =IFERROR(VLOOKUP($B28,'Sovereign Ratings Summary'!$B$10:$R$309,9,FALSE),"--") -> STA | H28: =IFERROR(VLOOKUP($B28,'Sovereign Ratings Summary'!$B$10:$R$309,11,FALSE),"--") -> Aaa | I28: =IFERROR(VLOOKUP($B28,'Sovereign Ratings Summary'!$B$10:$R$309,13,FALSE),"--") -> Aaa | K28: =IFERROR(VLOOKUP($B28,'Sovereign Ratings Summary'!$B$10:$R$309,15,FALSE),"--") -> Aaa | L28: =IFERROR(VLOOKUP($B28,'Sovereign Ratings Summary'!$B$10:$R$309,17,FALSE),"--") -> Aaa | N28: =""
A29: China | B29: China | C29: =IFERROR(VLOOKUP($B29,'Sovereign Ratings Summary'!$B$10:$R$309,3,FALSE),"--") -> A1 | D29: =IFERROR(VLOOKUP($B29,'Sovereign Ratings Summary'!$B$10:$R$309,5,FALSE),"--") -> STA | E29: =IFERROR(VLOOKUP($B29,'Sovereign Ratings Summary'!$B$10:$R$309,7,FALSE),"--") -> A1 | F29: =IFERROR(VLOOKUP($B29,'Sovereign Ratings Summary'!$B$10:$R$309,9,FALSE),"--") -> STA | H29: =IFERROR(VLOOKUP($B29,'Sovereign Ratings Summary'!$B$10:$R$309,11,FALSE),"--") -> Aa1 | I29: =IFERROR(VLOOKUP($B29,'Sovereign Ratings Summary'!$B$10:$R$309,13,FALSE),"--") -> Aa1 | K29: =IFERROR(VLOOKUP($B29,'Sovereign Ratings Summary'!$B$10:$R$309,15,FALSE),"--") -> Aaa | L29: =IFERROR(VLOOKUP($B29,'Sovereign Ratings Summary'!$B$10:$R$309,17,FALSE),"--") -> Aaa | N29: =""
A30: Colombia | B30: Colombia | C30: =IFERROR(VLOOKUP($B30,'Sovereign Ratings Summary'!$B$10:$R$309,3,FALSE),"--") -> Baa3 | D30: =IFERROR(VLOOKUP($B30,'Sovereign Ratings Summary'!$B$10:$R$309,5,FALSE),"--") -> STA | E30: =IFERROR(VLOOKUP($B30,'Sovereign Ratings Summary'!$B$10:$R$309,7,FALSE),"--") -> Baa3 | F30: =IFERROR(VLOOKUP($B30,'Sovereign Ratings Summary'!$B$10:$R$309,9,FALSE),"--") -> STA | H30: =IFERROR(VLOOKUP($B30,'Sovereign Ratings Summary'!$B$10:$R$309,11,FALSE),"--") -> A2 | I30: =IFERROR(VLOOKUP($B30,'Sovereign Ratings Summary'!$B$10:$R$309,13,FALSE),"--") -> A1 | K30: =IFERROR(VLOOKUP($B30,'Sovereign Ratings Summary'!$B$10:$R$309,15,FALSE),"--") -> A2 | L30: =IFERROR(VLOOKUP($B30,'Sovereign Ratings Summary'!$B$10:$R$309,17,FALSE),"--") -> A1 | N30: =""
A31: Costa Rica | B31: Costa Rica | C31: =IFERROR(VLOOKUP($B31,'Sovereign Ratings Summary'!$B$10:$R$309,3,FALSE),"--") -> Ba2 | D31: =IFERROR(VLOOKUP($B31,'Sovereign Ratings Summary'!$B$10:$R$309,5,FALSE),"--") -> STA | E31: =IFERROR(VLOOKUP($B31,'Sovereign Ratings Summary'!$B$10:$R$309,7,FALSE),"--") -> Ba2 | F31: =IFERROR(VLOOKUP($B31,'Sovereign Ratings Summary'!$B$10:$R$309,9,FALSE),"--") -> STA | H31: =IFERROR(VLOOKUP($B31,'Sovereign Ratings Summary'!$B$10:$R$309,11,FALSE),"--") -> Baa3 | I31: =IFERROR(VLOOKUP($B31,'Sovereign Ratings Summary'!$B$10:$R$309,13,FALSE),"--") -> Ba3 | K31: =IFERROR(VLOOKUP($B31,'Sovereign Ratings Summary'!$B$10:$R$309,15,FALSE),"--") -> Baa1 | L31: =IFERROR(VLOOKUP($B31,'Sovereign Ratings Summary'!$B$10:$R$309,17,FALSE),"--") -> Ba1 | N31: =""
A32: Croatia | B32: Croatia | C32: =IFERROR(VLOOKUP($B32,'Sovereign Ratings Summary'!$B$10:$R$309,3,FALSE),"--") -> A3 | D32: =IFERROR(VLOOKUP($B32,'Sovereign Ratings Summary'!$B$10:$R$309,5,FALSE),"--") -> STA | E32: =IFERROR(VLOOKUP($B32,'Sovereign Ratings Summary'!$B$10:$R$309,7,FALSE),"--") -> A3 | F32: =IFERROR(VLOOKUP($B32,'Sovereign Ratings Summary'!$B$10:$R$309,9,FALSE),"--") -> STA | H32: =IFERROR(VLOOKUP($B32,'Sovereign Ratings Summary'!$B$10:$R$309,11,FALSE),"--") -> Aaa | I32: =IFERROR(VLOOKUP($B32,'Sovereign Ratings Summary'!$B$10:$R$309,13,FALSE),"--") -> A2 | K32: =IFERROR(VLOOKUP($B32,'Sovereign Ratings Summary'!$B$10:$R$309,15,FALSE),"--") -> Aaa | L32: =IFERROR(VLOOKUP($B32,'Sovereign Ratings Summary'!$B$10:$R$309,17,FALSE),"--") -> A2 | N32: =""
... A71: Malaysia | B71: Malaysia | C71: =IFERROR(VLOOKUP($B71,'Sovereign Ratings Summary'!$B$10:$R$309,3,FALSE),"--") -> A3 | D71: =IFERROR(VLOOKUP($B71,'Sovereign Ratings Summary'!$B$10:$R$309,5,FALSE),"--") -> STA | E71: =IFERROR(VLOOKUP($B71,'Sovereign Ratings Summary'!$B$10:$R$309,7,FALSE),"--") -> A3 | F71: =IFERROR(VLOOKUP($B71,'Sovereign Ratings Summary'!$B$10:$R$309,9,FALSE),"--") -> STA | H71: =IFERROR(VLOOKUP($B71,'Sovereign Ratings Summary'!$B$10:$R$309,11,FALSE),"--") -> Aa2 | I71: =IFERROR(VLOOKUP($B71,'Sovereign Ratings Summary'!$B$10:$R$309,13,FALSE),"--") -> Aa2 | K71: =IFERROR(VLOOKUP($B71,'Sovereign Ratings Summary'!$B$10:$R$309,15,FALSE),"--") -> Aa1 | L71: =IFERROR(VLOOKUP($B71,'Sovereign Ratings Summary'!$B$10:$R$309,17,FALSE),"--") -> Aa1 | N71: =""
A72: Malta | B72: Malta | C72: =IFERROR(VLOOKUP($B72,'Sovereign Ratings Summary'!$B$10:$R$309,3,FALSE),"--") -> A2 | D72: =IFERROR(VLOOKUP($B72,'Sovereign Ratings Summary'!$B$10:$R$309,5,FALSE),"--") -> STA | E72: =IFERROR(VLOOKUP($B72,'Sovereign Ratings Summary'!$B$10:$R$309,7,FALSE),"--") -> A2 | F72: =IFERROR(VLOOKUP($B72,'Sovereign Ratings Summary'!$B$10:$R$309,9,FALSE),"--") -> STA | H72: =IFERROR(VLOOKUP($B72,'Sovereign Ratings Summary'!$B$10:$R$309,11,FALSE),"--") -> Aaa | I72: =IFERROR(VLOOKUP($B72,'Sovereign Ratings Summary'!$B$10:$R$309,13,FALSE),"--") -> Aaa | K72: =IFERROR(VLOOKUP($B72,'Sovereign Ratings Summary'!$B$10:$R$309,15,FALSE),"--") -> Aaa | L72: =IFERROR(VLOOKUP($B72,'Sovereign Ratings Summary'!$B$10:$R$309,17,FALSE),"--") -> Aaa
A73: Mauritius | B73: Mauritius | C73: =IFERROR(VLOOKUP($B73,'Sovereign Ratings Summary'!$B$10:$R$309,3,FALSE),"--") -> Baa3 | D73: =IFERROR(VLOOKUP($B73,'Sovereign Ratings Summary'!$B$10:$R$309,5,FALSE),"--") -> NEG | E73: =IFERROR(VLOOKUP($B73,'Sovereign Ratings Summary'!$B$10:$R$309,7,FALSE),"--") -> Baa3 | F73: =IFERROR(VLOOKUP($B73,'Sovereign Ratings Summary'!$B$10:$R$309,9,FALSE),"--") -> NEG | H73: =IFERROR(VLOOKUP($B73,'Sovereign Ratings Summary'!$B$10:$R$309,11,FALSE),"--") -> A2 | I73: =IFERROR(VLOOKUP($B73,'Sovereign Ratings Summary'!$B$10:$R$309,13,FALSE),"--") -> Aa3 | K73: =IFERROR(VLOOKUP($B73,'Sovereign Ratings Summary'!$B$10:$R$309,15,FALSE),"--") -> A2 | L73: =IFERROR(VLOOKUP($B73,'Sovereign Ratings Summary'!$B$10:$R$309,17,FALSE),"--") -> Aa3 | N73: =""
A74: Mexico | B74: Mexico | C74: =IFERROR(VLOOKUP($B74,'Sovereign Ratings Summary'!$B$10:$R$309,3,FALSE),"--") -> Baa2 | D74: =IFERROR(VLOOKUP($B74,'Sovereign Ratings Summary'!$B$10:$R$309,5,FALSE),"--") -> NEG | E74: =IFERROR(VLOOKUP($B74,'Sovereign Ratings Summary'!$B$10:$R$309,7,FALSE),"--") -> Baa2 | F74: =IFERROR(VLOOKUP($B74,'Sovereign Ratings Summary'!$B$10:$R$309,9,FALSE),"--") -> NEG | H74: =IFERROR(VLOOKUP($B74,'Sovereign Ratings Summary'!$B$10:$R$309,11,FALSE),"--") -> A1 | I74: =IFERROR(VLOOKUP($B74,'Sovereign Ratings Summary'!$B$10:$R$309,13,FALSE),"--") -> Aa3 | K74: =IFERROR(VLOOKUP($B74,'Sovereign Ratings Summary'!$B$10:$R$309,15,FALSE),"--") -> A1 | L74: =IFERROR(VLOOKUP($B74,'Sovereign Ratings Summary'!$B$10:$R$309,17,FALSE),"--") -> Aa3 | N74: =""
A75: Moldova | B75: Moldova | C75: =IFERROR(VLOOKUP($B75,'Sovereign Ratings Summary'!$B$10:$R$309,3,FALSE),"--") -> B2 | D75: =IFERROR(VLOOKUP($B75,'Sovereign Ratings Summary'!$B$10:$R$309,5,FALSE),"--") -> STA | E75: =IFERROR(VLOOKUP($B75,'Sovereign Ratings Summary'!$B$10:$R$309,7,FALSE),"--") -> B2 | F75: =IFERROR(VLOOKUP($B75,'Sovereign Ratings Summary'!$B$10:$R$309,9,FALSE),"--") -> STA | H75: =IFERROR(VLOOKUP($B75,'Sovereign Ratings Summary'!$B$10:$R$309,11,FALSE),"--") -> B1 | I75: =IFERROR(VLOOKUP($B75,'Sovereign Ratings Summary'!$B$10:$R$309,13,FALSE),"--") -> B2 | K75: =IFERROR(VLOOKUP($B75,'Sovereign Ratings Summary'!$B$10:$R$309,15,FALSE),"--") -> Ba2 | L75: =IFERROR(VLOOKUP($B75,'Sovereign Ratings Summary'!$B$10:$R$309,17,FALSE),"--") -> Ba3 | N75: =""
A76: Mongolia | B76: Mongolia | C76: =IFERROR(VLOOKUP($B76,'Sovereign Ratings Summary'!$B$10:$R$309,3,FALSE),"--") -> B1 | D76: =IFERROR(VLOOKUP($B76,'Sovereign Ratings Summary'!$B$10:$R$309,5,FALSE),"--") -> STA | E76: =IFERROR(VLOOKUP($B76,'Sovereign Ratings Summary'!$B$10:$R$309,7,FALSE),"--") -> B1 | F76: =IFERROR(VLOOKUP($B76,'Sovereign Ratings Summary'!$B$10:$R$309,9,FALSE),"--") -> STA | H76: =IFERROR(VLOOKUP($B76,'Sovereign Ratings Summary'!$B$10:$R$309,11,FALSE),"--") -> B1 | I76: =IFERROR(VLOOKUP($B76,'Sovereign Ratings Summary'!$B$10:$R$309,13,FALSE),"--") -> B3 | K76: =IFERROR(VLOOKUP($B76,'Sovereign Ratings Summary'!$B$10:$R$309,15,FALSE),"--") -> Ba2 | L76: =IFERROR(VLOOKUP($B76,'Sovereign Ratings Summary'!$B$10:$R$309,17,FALSE),"--") -> B1 | N76: =""
A77: Montenegro | B77: Montenegro | C77: =IFERROR(VLOOKUP($B77,'Sovereign Ratings Summary'!$B$10:$R$309,3,FALSE),"--") -> Ba3 | D77: =IFERROR(VLOOKUP($B77,'Sovereign Ratings Summary'!$B$10:$R$309,5,FALSE),"--") -> POS | E77: =IFERROR(VLOOKUP($B77,'Sovereign Ratings Summary'!$B$10:$R$309,7,FALSE),"--") -> - | F77: =IFERROR(VLOOKUP($B77,'Sovereign Ratings Summary'!$B$10:$R$309,9,FALSE),"--") -> - | H77: =IFERROR(VLOOKUP($B77,'Sovereign Ratings Summary'!$B$10:$R$309,11,FALSE),"--") -> Baa2 | I77: =IFERROR(VLOOKUP($B77,'Sovereign Ratings Summary'!$B$10:$R$309,13,FALSE),"--") -> Baa3 | K77: =IFERROR(VLOOKUP($B77,'Sovereign Ratings Summary'!$B$10:$R$309,15,FALSE),"--") -> - | L77: =IFERROR(VLOOKUP($B77,'Sovereign Ratings Summary'!$B$10:$R$309,17,FALSE),"--") -> - | N77: =""
A78: Morocco | B78: Morocco | C78: =IFERROR(VLOOKUP($B78,'Sovereign Ratings Summary'!$B$10:$R$309,3,FALSE),"--") -> Ba1 | D78: =IFERROR(VLOOKUP($B78,'Sovereign Ratings Summary'!$B$10:$R$309,5,FALSE),"--") -> POS | E78: =IFERROR(VLOOKUP($B78,'Sovereign Ratings Summary'!$B$10:$R$309,7,FALSE),"--") -> Ba1 | F78: =IFERROR(VLOOKUP($B78,'Sovereign Ratings Summary'!$B$10:$R$309,9,FALSE),"--") -> POS | H78: =IFERROR(VLOOKUP($B78,'Sovereign Ratings Summary'!$B$10:$R$309,11,FALSE),"--") -> Baa2 | I78: =IFERROR(VLOOKUP($B78,'Sovereign Ratings Summary'!$B$10:$R$309,13,FALSE),"--") -> Baa2 | K78: =IFERROR(VLOOKUP($B78,'Sovereign Ratings Summary'!$B$10:$R$309,15,FALSE),"--") -> Baa1 | L78: =IFERROR(VLOOKUP($B78,'Sovereign Ratings Summary'!$B$10:$R$309,17,FALSE),"--") -> Baa1 | N78: =""
A79: Namibia | B79: Namibia | C79: =IFERROR(VLOOKUP($B79,'Sovereign Ratings Summary'!$B$10:$R$309,3,FALSE),"--") -> B1 | D79: =IFERROR(VLOOKUP($B79,'Sovereign Ratings Summary'!$B$10:$R$309,5,FALSE),"--") -> POS | E79: =IFERROR(VLOOKUP($B79,'Sovereign Ratings Summary'!$B$10:$R$309,7,FALSE),"--") -> B1 | F79: =IFERROR(VLOOKUP($B79,'Sovereign Ratings Summary'!$B$10:$R$309,9,FALSE),"--") -> POS | H79: =IFERROR(VLOOKUP($B79,'Sovereign Ratings Summary'!$B$10:$R$309,11,FALSE),"--") -> Ba1 | I79: =IFERROR(VLOOKUP($B79,'Sovereign Ratings Summary'!$B$10:$R$309,13,FALSE),"--") -> Ba1 | K79: =IFERROR(VLOOKUP($B79,'Sovereign Ratings Summary'!$B$10:$R$309,15,FALSE),"--") -> Baa3 | L79: =IFERROR(VLOOKUP($B79,'Sovereign Ratings Summary'!$B$10:$R$309,17,FALSE),"--") -> Baa2 | N79: =""
A80: Netherlands | B80: Netherlands | C80: =IFERROR(VLOOKUP($B80,'Sovereign Ratings Summary'!$B$10:$R$309,3,FALSE),"--") -> Aaa | D80: =IFERROR(VLOOKUP($B80,'Sovereign Ratings Summary'!$B$10:$R$309,5,FALSE),"--") -> STA | E80: =IFERROR(VLOOKUP($B80,'Sovereign Ratings Summary'!$B$10:$R$309,7,FALSE),"--") -> Aaa | F80: =IFERROR(VLOOKUP($B80,'Sovereign Ratings Summary'!$B$10:$R$309,9,FALSE),"--") -> STA | H80: =IFERROR(VLOOKUP($B80,'Sovereign Ratings Summary'!$B$10:$R$309,11,FALSE),"--") -> Aaa | I80: =IFERROR(VLOOKUP($B80,'Sovereign Ratings Summary'!$B$10:$R$309,13,FALSE),"--") -> Aaa | K80: =IFERROR(VLOOKUP($B80,'Sovereign Ratings Summary'!$B$10:$R$309,15,FALSE),"--") -> Aaa | L80: =IFERROR(VLOOKUP($B80,'Sovereign Ratings Summary'!$B$10:$R$309,17,FALSE),"--") -> Aaa | N80: =""
...
